<?xml version="1.0" encoding="utf-8"?>
<!-- =================================================================================== -->
<!-- |    This document was autogenerated by xacro from ../urdf/utra6_850_robot.urdf.xacro | -->
<!-- |    EDITING THIS FILE BY HAND IS NOT RECOMMENDED                                 | -->
<!-- =================================================================================== -->
<robot name="utra6_850">
  <!--
    Author: Jimy Zhang <jimy.zhang@umbratek.com> <jimy92@163.com>
    Contributers:
  -->
  <link name="world"/>
  <joint name="world_joint" type="fixed">
    <parent link="world"/>
    <child link="base_link"/>
    <origin rpy="0 0 0" xyz="0 0 0"/>
  </joint>
  <material name="Black">
    <color rgba="0.0 0.0 0.0 1.0"/>
  </material>
  <material name="Red">
    <color rgba="0.8 0.0 0.0 1.0"/>
  </material>
  <material name="White">
    <color rgba="1.0 1.0 1.0 1.0"/>
  </material>
  <material name="Silver">
    <color rgba="0.7 0.7 0.7 1.0"/>
  </material>
  <link name="base_link">
    <inertial>
      <origin rpy="0 0 0" xyz="0 0 0"/>
      <mass value="1e-05"/>
      <inertia ixx="0" ixy="0" ixz="0" iyy="0" iyz="0" izz="0"/>
    </inertial>
    <visual>
      <origin rpy="0 0 0" xyz="0 0 0"/>
      <geometry>
        <mesh filename="package://arm_description/meshes/utra6_850/visual/base.STL"/>
      </geometry>
      <material name="Silver"/>
    </visual>
    <collision>
      <origin rpy="0 0 0" xyz="0 0 0"/>
      <geometry>
        <mesh filename="package://arm_description/meshes/utra6_850/visual/base.STL"/>
      </geometry>
    </collision>
  </link>
  <link name="link_1">
    <inertial>
      <origin rpy="0 0 0" xyz="0 0 0"/>
      <mass value="1e-05"/>
      <inertia ixx="0" ixy="0" ixz="0" iyy="0" iyz="0" izz="0"/>
    </inertial>
    <visual>
      <origin rpy="0 0 0" xyz="0 0 0"/>
      <geometry>
        <mesh filename="package://arm_description/meshes/utra6_850/visual/link1.STL"/>
      </geometry>
      <material name="Silver"/>
    </visual>
    <collision>
      <origin rpy="0 0 0" xyz="0 0 0"/>
      <geometry>
        <mesh filename="package://arm_description/meshes/utra6_850/visual/link1.STL"/>
      </geometry>
    </collision>
  </link>
  <link name="link_2">
    <inertial>
      <origin rpy="0 0 0" xyz="0 0 0"/>
      <mass value="1e-05"/>
      <inertia ixx="0" ixy="0" ixz="0" iyy="0" iyz="0" izz="0"/>
    </inertial>
    <visual>
      <origin rpy="0 0 0" xyz="0 0 0"/>
      <geometry>
        <mesh filename="package://arm_description/meshes/utra6_850/visual/link2.STL"/>
      </geometry>
      <material name="Silver"/>
    </visual>
    <collision>
      <origin rpy="0 0 0" xyz="0 0 0"/>
      <geometry>
        <mesh filename="package://arm_description/meshes/utra6_850/visual/link2.STL"/>
      </geometry>
    </collision>
  </link>
  <joint name="joint3" type="revolute">
    <origin rpy="0 0 0" xyz="0 0 0.3895"/>
    <parent link="link_2"/>
    <child link="link_3"/>
    <axis xyz="0 1 0"/>
    <limit effort="0" lower="-6.28318530718" upper="6.28318530718" velocity="3.14"/>
    <dynamics damping="0" friction="0"/>
  </joint>
  <link name="link_3">
    <inertial>
      <origin rpy="0 0 0" xyz="0 0 0"/>
      <mass value="1e-05"/>
      <inertia ixx="0" ixy="0" ixz="0" iyy="0" iyz="0" izz="0"/>
    </inertial>
    <visual>
      <origin rpy="0 0 0" xyz="0 0 0"/>
      <geometry>
        <mesh filename="package://arm_description/meshes/utra6_850/visual/link3.STL"/>
      </geometry>
      <material name="Silver"/>
    </visual>
    <collision>
      <origin rpy="0 0 0" xyz="0 0 0"/>
      <geometry>
        <mesh filename="package://arm_description/meshes/utra6_850/visual/link3.STL"/>
      </geometry>
    </collision>
  </link>
  <link name="link_4">
    <inertial>
      <origin rpy="0 0 0" xyz="0 0 0"/>
      <mass value="1e-05"/>
      <inertia ixx="0" ixy="0" ixz="0" iyy="0" iyz="0" izz="0"/>
    </inertial>
    <visual>
      <origin rpy="0 0 0" xyz="0 0 0"/>
      <geometry>
        <mesh filename="package://arm_description/meshes/utra6_850/visual/link4.STL"/>
      </geometry>
      <material name="Silver"/>
    </visual>
    <collision>
      <origin rpy="0 0 0" xyz="0 0 0"/>
      <geometry>
        <mesh filename="package://arm_description/meshes/utra6_850/visual/link4.STL"/>
      </geometry>
    </collision>
  </link>
  <joint name="joint5" type="revolute">
    <origin rpy="0 0 0" xyz="0 -0.1245 0.0965"/>
    <parent link="link_4"/>
    <child link="link_5"/>
    <axis xyz="0 0 1"/>
    <limit effort="0" lower="-6.28318530718" upper="6.28318530718" velocity="3.14"/>
    <dynamics damping="0" friction="0"/>
  </joint>
  <link name="link_5">
    <inertial>
      <mass value="1e-05"/>
      <origin rpy="0 0 0" xyz="0 0 0"/>
      <inertia ixx="0" ixy="0" ixz="0" iyy="0" iyz="0" izz="0"/>
    </inertial>
    <visual>
      <origin rpy="0 0 0" xyz="0 0 0"/>
      <geometry>
        <mesh filename="package://arm_description/meshes/utra6_850/visual/link5.STL"/>
      </geometry>
      <material name="Silver"/>
    </visual>
    <collision>
      <origin rpy="0 0 0" xyz="0 0 0"/>
      <geometry>
        <mesh filename="package://arm_description/meshes/utra6_850/visual/link5.STL"/>
      </geometry>
    </collision>
  </link>
  <link name="link_6">
    <inertial>
      <mass value="1e-05"/>
      <origin rpy="0 0 0" xyz="0 0 0"/>
      <inertia ixx="0" ixy="0" ixz="0" iyy="0" iyz="0" izz="0"/>
    </inertial>
    <visual>
      <origin rpy="0 0 0" xyz="0 0 0"/>
      <geometry>
        <mesh filename="package://arm_description/meshes/utra6_850/visual/link6.STL"/>
      </geometry>
      <material name="Silver"/>
    </visual>
    <collision>
      <origin rpy="0 0 0" xyz="0 0 0"/>
      <geometry>
        <mesh filename="package://arm_description/meshes/utra6_850/visual/link6.STL"/>
      </geometry>
    </collision>
  </link>

    <!--ADDPOINT1START-->
    <link name="tool0">
      <inertial>
        <origin rpy="0 0 0" xyz="1.10509452800074E-06 0.00208243198225818 0.0400984076446437"/>
        <mass value="0.185199260372416"/>
        <inertia ixx="9.76222430788153E-05" ixy="-7.8112390093605E-09" ixz="6.20208431775755E-12" iyy="8.20988447730316E-05" iyz="-3.40692325998543E-06" izz="0.000149625833719171"/>
      </inertial>
      <visual>
        <origin rpy="0 0 0" xyz="0 0 0"/>
        <geometry>
          <mesh filename="package://motoman_description/meshes/grippers/six_fingered_gripper/base_gripper.STL"/>
        </geometry>
        <material name="">
          <color rgba="0.752941176470588 0.752941176470588 0.752941176470588 1"/>
        </material>
      </visual>
      <!-- xyz="${0.0392698743200124} ${0.0120111889614487-0.095} ${0.0400984080168193-0.03}" /> -->
      <collision>     <!--collisionの記述をアクティブに変更-->
        <origin
          xyz="0 0 0"
          rpy="0 0 0" />
        <geometry>
          <mesh
            filename="package://motoman_description/meshes/grippers/six_fingered_gripper/base_gripper.STL" />
        </geometry>
      </collision>
    </link>
    <link name="gripper_finger_1">
      <inertial>
        <origin rpy="0 0 0" xyz="-0.0012619 0.038986 -2.3657E-12"/>
        <mass value="0.006157"/>
        <inertia ixx="2.4192E-06" ixy="2.4793E-07" ixz="2.8628E-15" iyy="1.6776E-07" iyz="1.1444E-15" izz="2.5199E-06"/>
      </inertial>
      <visual>
        <origin rpy="0 0 0" xyz="0 0 0"/>
        <geometry>
          <mesh filename="package://motoman_description/meshes/grippers/six_fingered_gripper/gripper_finger_1.STL"/>
        </geometry>
        <material name="">
          <color rgba="0.75294 0.75294 0.75294 1"/>
        </material>
      </visual>
      <collision>
        <origin
          xyz="0 0 0"
          rpy="0 0 0" />
        <geometry>
          <mesh
            filename="package://motoman_description/meshes/grippers/six_fingered_gripper/gripper_finger_1.STL" />
        </geometry>
      </collision>
    </link>
    <link name="gripper_finger_2">
      <inertial>
        <origin rpy="0 0 0" xyz="-0.0012619 0.038986 -2.3657E-12"/>
        <mass value="0.006157"/>
        <inertia ixx="2.4192E-06" ixy="2.4793E-07" ixz="2.8628E-15" iyy="1.6776E-07" iyz="1.1444E-15" izz="2.5199E-06"/>
      </inertial>
      <visual>
        <origin rpy="0 0 0" xyz="0 0 0"/>
        <geometry>
          <mesh filename="package://motoman_description/meshes/grippers/six_fingered_gripper/gripper_finger_2.STL"/>
        </geometry>
        <material name="">
          <color rgba="0.75294 0.75294 0.75294 1"/>
        </material>
      </visual>
      <collision>
        <origin
          xyz="0 0 0"
          rpy="0 0 0" />
        <geometry>
          <mesh
            filename="package://motoman_description/meshes/grippers/six_fingered_gripper/gripper_finger_2.STL" />
        </geometry>
      </collision>
    </link>
    <link name="gripper_finger_3">
      <inertial>
        <origin rpy="0 0 0" xyz="-0.0012619 0.038986 -2.3657E-12"/>
        <mass value="0.006157"/>
        <inertia ixx="2.4192E-06" ixy="2.4793E-07" ixz="2.8628E-15" iyy="1.6776E-07" iyz="1.1444E-15" izz="2.5199E-06"/>
      </inertial>
      <visual>
        <origin rpy="0 0 0" xyz="0 0 0"/>
        <geometry>
          <mesh filename="package://motoman_description/meshes/grippers/six_fingered_gripper/gripper_finger_3.STL"/>
        </geometry>
        <material name="">
          <color rgba="0.75294 0.75294 0.75294 1"/>
        </material>
      </visual>
      <collision>
        <origin
          xyz="0 0 0"
          rpy="0 0 0" />
        <geometry>
          <mesh
            filename="package://motoman_description/meshes/grippers/six_fingered_gripper/gripper_finger_3.STL" />
        </geometry>
      </collision>
    </link>
    <link name="gripper_finger_4">
      <inertial>
        <origin rpy="0 0 0" xyz="-0.00126191047827026 0.0389862430346049 -2.36565281253043E-12"/>
        <mass value="0.00615698496047359"/>
        <inertia ixx="2.41915556010585E-06" ixy="2.47931048420401E-07" ixz="2.86284769490924E-15" iyy="1.67755649991034E-07" iyz="1.14444598796065E-15" izz="2.51994852952969E-06"/>
      </inertial>
      <visual>
        <origin rpy="0 0 0" xyz="0 0 0"/>
        <geometry>
          <mesh filename="package://motoman_description/meshes/grippers/six_fingered_gripper/gripper_finger_4.STL"/>
        </geometry>
        <material name="">
          <color rgba="0.752941176470588 0.752941176470588 0.752941176470588 1"/>
        </material>
      </visual>
      <collision>
        <origin
          xyz="0 0 0"
          rpy="0 0 0" />
        <geometry>
          <mesh
            filename="package://motoman_description/meshes/grippers/six_fingered_gripper/gripper_finger_4.STL" />
        </geometry>
      </collision>
    </link>
    <link name="gripper_finger_5">
      <inertial>
        <origin rpy="0 0 0" xyz="-0.0012619 0.038986 -2.3657E-12"/>
        <mass value="0.006157"/>
        <inertia ixx="2.4192E-06" ixy="2.4793E-07" ixz="2.8628E-15" iyy="1.6776E-07" iyz="1.1444E-15" izz="2.5199E-06"/>
      </inertial>
      <visual>
        <origin rpy="0 0 0" xyz="0 0 0"/>
        <geometry>
          <mesh filename="package://motoman_description/meshes/grippers/six_fingered_gripper/gripper_finger_5.STL"/>
        </geometry>
        <material name="">
          <color rgba="0.75294 0.75294 0.75294 1"/>
        </material>
      </visual>
      <collision>
        <origin
          xyz="0 0 0"
          rpy="0 0 0" />
        <geometry>
          <mesh
            filename="package://motoman_description/meshes/grippers/six_fingered_gripper/gripper_finger_5.STL" />
        </geometry>
      </collision>
    </link>
    <link name="gripper_finger_6">
      <inertial>
        <origin rpy="0 0 0" xyz="-0.0012619 0.038986 -2.3657E-12"/>
        <mass value="0.006157"/>
        <inertia ixx="2.4192E-06" ixy="2.4793E-07" ixz="2.8628E-15" iyy="1.6776E-07" iyz="1.1444E-15" izz="2.5199E-06"/>
      </inertial>
      <visual>
        <origin rpy="0 0 0" xyz="0 0 0"/>
        <geometry>
          <mesh filename="package://motoman_description/meshes/grippers/six_fingered_gripper/gripper_finger_6.STL"/>
        </geometry>
        <material name="">
          <color rgba="0.75294 0.75294 0.75294 1"/>
        </material>
      </visual>
      <collision>
        <origin
          xyz="0 0 0"
          rpy="0 0 0" />
        <geometry>
          <mesh
            filename="package://motoman_description/meshes/grippers/six_fingered_gripper/gripper_finger_6.STL" />
        </geometry>
      </collision>
    </link>
    <!--ADDPOINT1END-->




  

  <joint name="joint1" type="revolute">
    <origin rpy="0 0 0" xyz="0 0 0"/>
    <parent link="base_link"/>
    <child link="link_1"/>
    <axis xyz="0 0 1"/>
    <limit effort="0" lower="-6.28318530718" upper="6.28318530718" velocity="3.14"/>
    <dynamics damping="0" friction="0"/>
  </joint>
  <joint name="joint2" type="revolute">
    <origin rpy="0 0 0" xyz="0 0 0.0935"/>
    <parent link="link_1"/>
    <child link="link_2"/>
    <axis xyz="0 -1 0"/>
    <limit effort="0" lower="-6.28318530718" upper="6.28318530718" velocity="3.14"/>
    <dynamics damping="0" friction="0"/>
  </joint>
  <joint name="joint3" type="revolute">
    <origin rpy="0 0 0" xyz="0 0 0.3895"/>
    <parent link="link_2"/>
    <child link="link_3"/>
    <axis xyz="0 1 0"/>
    <limit effort="0" lower="-6.28318530718" upper="6.28318530718" velocity="3.14"/>
    <dynamics damping="0" friction="0"/>
  </joint>
  <joint name="joint4" type="revolute">
    <origin rpy="0 0 0" xyz="0 0 0.364"/>
    <parent link="link_3"/>
    <child link="link_4"/>
    <axis xyz="0 -1 0"/>
    <limit effort="0" lower="-6.28318530718" upper="6.28318530718" velocity="3.14"/>
    <dynamics damping="0" friction="0"/>
  </joint>
  <joint name="joint5" type="revolute">
    <origin rpy="0 0 0" xyz="0 -0.1245 0.0965"/>
    <parent link="link_4"/>
    <child link="link_5"/>
    <axis xyz="0 0 1"/>
    <limit effort="0" lower="-6.28318530718" upper="6.28318530718" velocity="3.14"/>
    <dynamics damping="0" friction="0"/>
  </joint>
  <joint name="joint6" type="revolute">
    <origin rpy="1.57079632679 0 0" xyz="0 -0.0665 0"/>
    <parent link="link_5"/>
    <child link="link_6"/>
    <axis xyz="0 0 1"/>
    <limit effort="0" lower="-6.28318530718" upper="6.28318530718" velocity="3.14"/>
    <dynamics damping="0" friction="0"/>
  </joint>

  <joint name="joint_tool0" type="fixed">
    <origin rpy="-1.5708 0 1.5708" xyz="0.0115 0 0"/>
    <!-- <origin rpy="0 0 0" xyz="0.34 0 0"/> -->
    <parent link="link_6"/>
    <child link="tool0"/>
  </joint>
  <!--ADDPOINT2START-->
  <joint name="finger_joint_1" type="revolute">
    <origin rpy="0 1.0472 -3.1416" xyz="0.0175 -0.08 0.030311"/>
    <parent link="tool0"/>
    <child link="gripper_finger_1"/>
    <axis xyz="0 0 1"/>
    <limit
      lower="-0.25"
      upper="0"
      effort="0.7"
      velocity="3" />
  </joint>
  <joint name="finger_joint_2" type="revolute">
    <origin rpy="0 0 3.1416" xyz="0.035 -0.08 0"/>
    <parent link="tool0"/>
    <child link="gripper_finger_2"/>
    <axis xyz="0 0 1"/>
    <limit
      lower="-0.25"
      upper="0"
      effort="0.7"
      velocity="3" />
  </joint>
  <joint name="finger_joint_3" type="revolute">
    <origin rpy="0 -1.0472 3.1416" xyz="0.0175 -0.08 -0.030311"/>
    <parent link="tool0"/>
    <child link="gripper_finger_3"/>
    <axis xyz="0 0 1"/>
    <limit
      lower="-0.25"
      upper="0"
      effort="0.7"
      velocity="3" />
  </joint>
  <joint name="finger_joint_4" type="revolute">
    <origin rpy="3.1416 -1.0472 0" xyz="-0.0175 -0.08 -0.030311"/>
    <parent link="tool0"/>
    <child link="gripper_finger_4"/>
    <axis xyz="0 0 1"/>
    <limit
      lower="-0.25"
      upper="0"
      effort="0.7"
      velocity="3" />
  </joint>
  <joint name="finger_joint_5" type="revolute">
    <origin rpy="3.1416 0 0" xyz="-0.035 -0.08 0"/>
    <parent link="tool0"/>
    <child link="gripper_finger_5"/>
    <axis xyz="0 0 1"/>
    <limit
      lower="-0.25"
      upper="0"
      effort="0.7"
      velocity="3" />
  </joint>
  <joint name="finger_joint_6" type="revolute">
    <origin rpy="3.1416 1.0472 0" xyz="-0.0175 -0.08 0.030311"/>
    <parent link="tool0"/>
    <child link="gripper_finger_6"/>
    <axis xyz="0 0 1"/>
    <limit
      lower="-0.25"
      upper="0"
      effort="0.7"
      velocity="3" />
  </joint>
  <!--ADDPOINT2END-->


  <transmission name="tran1">
    <type>transmission_interface/SimpleTransmission</type>
    <joint name="joint1">
      <hardwareInterface>hardware_interface/PositionJointInterface</hardwareInterface>
    </joint>
    <actuator name="motor1">
      <hardwareInterface>hardware_interface/PositionJointInterface</hardwareInterface>
      <mechanicalReduction>1</mechanicalReduction>
    </actuator>
  </transmission>
  <transmission name="tran2">
    <type>transmission_interface/SimpleTransmission</type>
    <joint name="joint2">
      <hardwareInterface>hardware_interface/PositionJointInterface</hardwareInterface>
    </joint>
    <actuator name="motor2">
      <hardwareInterface>hardware_interface/PositionJointInterface</hardwareInterface>
      <mechanicalReduction>1</mechanicalReduction>
    </actuator>
  </transmission>
  <transmission name="tran3">
    <type>transmission_interface/SimpleTransmission</type>
    <joint name="joint3">
      <hardwareInterface>hardware_interface/PositionJointInterface</hardwareInterface>
    </joint>
    <actuator name="motor3">
      <hardwareInterface>hardware_interface/PositionJointInterface</hardwareInterface>
      <mechanicalReduction>1</mechanicalReduction>
    </actuator>
  </transmission>
  <transmission name="tran4">
    <type>transmission_interface/SimpleTransmission</type>
    <joint name="joint4">
      <hardwareInterface>hardware_interface/PositionJointInterface</hardwareInterface>
    </joint>
    <actuator name="motor4">
      <hardwareInterface>hardware_interface/PositionJointInterface</hardwareInterface>
      <mechanicalReduction>1</mechanicalReduction>
    </actuator>
  </transmission>
  <transmission name="tran5">
    <type>transmission_interface/SimpleTransmission</type>
    <joint name="joint5">
      <hardwareInterface>hardware_interface/PositionJointInterface</hardwareInterface>
    </joint>
    <actuator name="motor5">
      <hardwareInterface>hardware_interface/PositionJointInterface</hardwareInterface>
      <mechanicalReduction>1</mechanicalReduction>
    </actuator>
  </transmission>
  <transmission name="tran6">
    <type>transmission_interface/SimpleTransmission</type>
    <joint name="joint6">
      <hardwareInterface>hardware_interface/PositionJointInterface</hardwareInterface>
    </joint>
    <actuator name="motor6">
      <hardwareInterface>hardware_interface/PositionJointInterface</hardwareInterface>
      <mechanicalReduction>1</mechanicalReduction>
    </actuator>
  </transmission>
    <!--ADPOINT3START-->
    <transmission name="transmission_1">
      <type>transmission_interface/SimpleTransmission</type>
      <joint name="finger_joint_1">
        <hardwareInterface>PositionJointInterface</hardwareInterface>
     </joint>
      <actuator name="motor_1">
        <hardwareInterface>PositionJointInterface</hardwareInterface>
        <mechanicalReduction>10</mechanicalReduction>
      </actuator>
    </transmission>
    <transmission name="transmission_2">
      <type>transmission_interface/SimpleTransmission</type>
      <joint name="finger_joint_2">
        <hardwareInterface>PositionJointInterface</hardwareInterface>
     </joint>
      <actuator name="motor_2">
        <hardwareInterface>PositionJointInterface</hardwareInterface>
        <mechanicalReduction>10</mechanicalReduction>
      </actuator>
    </transmission>  <transmission name="transmission_3">
      <type>transmission_interface/SimpleTransmission</type>
      <joint name="finger_joint_3">
        <hardwareInterface>PositionJointInterface</hardwareInterface>
     </joint>
      <actuator name="motor_3">
        <hardwareInterface>PositionJointInterface</hardwareInterface>
        <mechanicalReduction>10</mechanicalReduction>
      </actuator>
    </transmission>  <transmission name="transmission_4">
      <type>transmission_interface/SimpleTransmission</type>
      <joint name="finger_joint_4">
        <hardwareInterface>PositionJointInterface</hardwareInterface>
     </joint>
      <actuator name="motor_4">
        <hardwareInterface>PositionJointInterface</hardwareInterface>
        <mechanicalReduction>10</mechanicalReduction>
      </actuator>
    </transmission>  <transmission name="transmission_5">
      <type>transmission_interface/SimpleTransmission</type>
      <joint name="finger_joint_5">
        <hardwareInterface>PositionJointInterface</hardwareInterface>
     </joint>
      <actuator name="motor_5">
        <hardwareInterface>PositionJointInterface</hardwareInterface>
        <mechanicalReduction>10</mechanicalReduction>
      </actuator>
    </transmission>  <transmission name="transmission_6">
      <type>transmission_interface/SimpleTransmission</type>
      <joint name="finger_joint_6">
        <hardwareInterface>PositionJointInterface</hardwareInterface>
     </joint>
      <actuator name="motor_6">
        <hardwareInterface>PositionJointInterface</hardwareInterface>
        <mechanicalReduction>10</mechanicalReduction>
      </actuator>
    </transmission>
    <!--ADDPOINT3END-->


  <gazebo>
    <plugin filename="libgazebo_ros_control.so" name="gazebo_ros_control">
      <robotNamespace>/utra6_850</robotNamespace>
      <robotSimType>gazebo_ros_control/DefaultRobotHWSim</robotSimType>
      <legacyModeNS>true</legacyModeNS>
    </plugin>
  </gazebo>



  <link name="eef_link"/>
  <joint name="tool0_ee_joint" type="fixed">
    <origin rpy="4.71238898038469 0 -1.5707963267948966" xyz="0.0 0 0"/>
    <!-- eef is at the center of gripper-->
    <parent link="tool0"/>
    <child link="eef_link"/>
  </joint>
  <link name="motoman_base">
    <visual>
      <geometry>
        <mesh filename="package://motoman_description/meshes/motoman_base/motoman_base.stl" scale="1 1 1"/>
      </geometry>
      <origin rpy="1.5707963267948966 0 1.5707963267948966" xyz="0 0 0"/>
      <material name="Green">
        <color rgba="0 1 0 0.5"/>
      </material>
    </visual>
    <collision>
      <geometry>
        <mesh filename="package://motoman_description/meshes/motoman_base/motoman_base.stl" scale="1 1 1"/>
      </geometry>
      <origin rpy="1.5707963267948966 0 1.5707963267948966" xyz="0 0 0"/>
    </collision>
  </link>
  <joint name="motoman_base_to_world" type="fixed">
    <parent link="world"/>
    <child link="motoman_base"/>
    <origin rpy="0 0 0" xyz="0.55 0.33 -0.5"/>
  </joint>

</robot>
