<?xml version="1.0" ?>
<!-- =================================================================================== -->
<!-- |    This document was autogenerated by xacro from xarm7_robot.urdf.xacro         | -->
<!-- |    EDITING THIS FILE BY HAND IS NOT RECOMMENDED                                 | -->
<!-- =================================================================================== -->
<robot name="xarm7" xmlns:xacro="http://ros.org/wiki/xacro">
  <!--
  Author: Jimy Zhang <jimy.zhang@ufactory.cc> <jimy92@163.com>
  Contributers:
-->

  <material name="Black">
    <color rgba="0.0 0.0 0.0 1.0"/>
  </material>
  <material name="Red">
    <color rgba="0.8 0.0 0.0 1.0"/>
  </material>
  <material name="White">
    <color rgba="1.0 1.0 1.0 1.0"/>
  </material>
  <material name="Silver">
    <color rgba="0.753 0.753 0.753 1.0"/>
  </material>
  <!-- ADDPOINT0START -->
  <material name="green">
    <color rgba="0.0 0.8 0.0 1.0"/>
  </material>
  <!-- ADDPOINT0END -->
  <link name="link_base">
    <inertial>
      <origin rpy="0 0 0" xyz="-0.021131 -0.0016302 0.056488"/>
      <mass value="0.88556"/>
      <inertia ixx="0.0030595" ixy="0.00012259" ixz="-0.00062705" iyy="0.0037783" iyz="0.00027023" izz="0.0020125"/>
    </inertial>
    <visual>
      <origin rpy="0 0 0" xyz="0 0 0"/>
      <geometry>
        <mesh filename="meshes/xarm7/visual/link_base_smooth.STL"/>
      </geometry>
      <material name="White"/>
    </visual>
    <collision>
      <origin rpy="0 0 0" xyz="0 0 0"/>
      <geometry>
        <mesh filename="meshes/xarm7/collision/linkbase.obj"/>
      </geometry>
    </collision>
  </link>
  <link name="link1">
    <inertial>
      <origin rpy="0 0 0" xyz="-0.0042142 0.02821 -0.0087788"/>
      <mass value="0.42603"/>
      <inertia ixx="0.0014243" ixy="3.9946E-05" ixz="4.7078E-06" iyy="0.00123" iyz="-0.00026073" izz="0.00099229"/>
    </inertial>
    <visual>
      <origin rpy="0 0 0" xyz="0 0 0"/>
      <geometry>
        <mesh filename="meshes/xarm7/visual/link1_smooth.STL"/>
      </geometry>
      <material name="White"/>
    </visual>
    <collision>
      <origin rpy="0 0 0" xyz="0 0 0"/>
      <geometry>
        <mesh filename="meshes/xarm7/collision/link1_vhacd.obj"/>
      </geometry>
    </collision>
  </link>

  <link name="link2">
    <inertial>
      <origin rpy="0 0 0" xyz="-3.3178E-05 -0.12849 0.026337"/>
      <mass value="0.56095"/>
      <inertia ixx="0.0031915" ixy="3.0892E-06" ixz="2.8729E-06" iyy="0.0017468" iyz="-0.0010241" izz="0.00235"/>
    </inertial>
    <visual>
      <origin rpy="0 0 0" xyz="0 0 0"/>
      <geometry>
        <mesh filename="meshes/xarm7/visual/link2_smooth.STL"/>
      </geometry>
      <material name="White"/>
    </visual>
    <collision>
      <origin rpy="0 0 0" xyz="0 0 0"/>
      <geometry>
        <mesh filename="meshes/xarm7/collision/link2_vhacd.obj"/>
      </geometry>
    </collision>
  </link>

  <link name="link3">
    <inertial>
      <origin rpy="0 0 0" xyz="0.04223 -0.023258 -0.0096674"/>
      <mass value="0.44463"/>
      <inertia ixx="0.0011454" ixy="0.0001654" ixz="-0.0001951" iyy="0.0010503" iyz="0.00012027" izz="0.0011083"/>
    </inertial>
    <visual>
      <origin rpy="0 0 0" xyz="0 0 0"/>
      <geometry>
        <mesh filename="meshes/xarm7/visual/link3_smooth.STL"/>
      </geometry>
      <material name="White"/>
    </visual>
    <collision>
      <origin rpy="0 0 0" xyz="0 0 0"/>
      <geometry>
        <mesh filename="meshes/xarm7/collision/link3_vhacd.obj"/>
      </geometry>
    </collision>
  </link>

  <link name="link4">
    <inertial>
      <origin rpy="0 0 0" xyz="0.067148 -0.10732 0.024479"/>
      <mass value="0.52387"/>
      <inertia ixx="0.0026033" ixy="0.00053379" ixz="0.00036314" iyy="0.0017649" iyz="-0.00083253" izz="0.0022431"/>
    </inertial>
    <visual>
      <origin rpy="0 0 0" xyz="0 0 0"/>
      <geometry>
        <mesh filename="meshes/xarm7/visual/link4_smooth.STL"/>
      </geometry>
      <material name="White"/>
    </visual>
    <collision>
      <origin rpy="0 0 0" xyz="0 0 0"/>
      <geometry>
        <mesh filename="meshes/xarm7/collision/link4_vhacd.obj"/>
      </geometry>
    </collision>
  </link>

  <link name="link5">
    <inertial>
      <origin rpy="0 0 0" xyz="-0.00023397 0.036705 -0.080064"/>
      <mass value="0.18554"/>
      <inertia ixx="0.00099549" ixy="8.9957E-07" ixz="8.5285E-07" iyy="0.0008853" iyz="-0.00025682" izz="0.00035048"/>
    </inertial>
    <visual>
      <origin rpy="0 0 0" xyz="0 0 0"/>
      <geometry>
        <mesh filename="meshes/xarm7/visual/link5_smooth.STL"/>
      </geometry>
      <material name="White"/>
    </visual>
    <collision>
      <origin rpy="0 0 0" xyz="0 0 0"/>
      <geometry>
        <mesh filename="meshes/xarm7/collision/link5_vhacd.obj"/>
      </geometry>
    </collision>
  </link>

  <link name="link6">
    <inertial>
      <origin rpy="0 0 0" xyz="0.058911 0.028469 0.0068428"/>
      <mass value="0.31344"/>
      <inertia ixx="0.00052034" ixy="-0.00014989" ixz="0.00011658" iyy="0.00067968" iyz="6.116E-05" izz="0.00078345"/>
    </inertial>
    <visual>
      <origin rpy="0 0 0" xyz="0 0 0"/>
      <geometry>
        <mesh filename="meshes/xarm7/visual/link6_smooth.STL"/>
      </geometry>
      <material name="White"/>
    </visual>
    <collision>
      <origin rpy="0 0 0" xyz="0 0 0"/>
      <geometry>
        <mesh filename="meshes/xarm7/collision/link6_vhacd.obj"/>
      </geometry>
    </collision>
  </link>

  <link name="link7">
    <inertial>
      <origin rpy="0 0 0" xyz="-1.5846E-05 -0.0046377 -0.012705"/>
      <mass value="0.31468"/>
      <inertia ixx="0.00016985" ixy="1.1102E-07" ixz="5.1075E-08" iyy="0.00011924" iyz="-2.1251E-06" izz="0.00026032"/>
    </inertial>
    <visual>
      <origin rpy="0 0 0" xyz="0 0 0"/>
      <geometry>
        <mesh filename="meshes/xarm7/visual/link7_smooth.STL"/>
      </geometry>
      <material name="Silver"/>
    </visual>
    <collision>
      <origin rpy="0 0 0" xyz="0 0 0"/>
      <geometry>
        <mesh filename="meshes/xarm7/collision/link7_vhacd.obj"/>
      </geometry>
    </collision>
  </link>
  <!--ADDPOINT1START-->
  <link name="tool0">
    <inertial>
      <origin rpy="0 0 0" xyz="1.10509452800074E-06 0.00208243198225818 0.0400984076446437"/>
      <mass value="0.185199260372416"/>
      <inertia ixx="9.76222430788153E-05" ixy="-7.8112390093605E-09" ixz="6.20208431775755E-12" iyy="8.20988447730316E-05" iyz="-3.40692325998543E-06" izz="0.000149625833719171"/>
    </inertial>
    <visual>
      <origin rpy="0 0 0" xyz="0 0 0"/>
      <geometry>
        <mesh filename="meshes/grippers/six_fingered_gripper/base_gripper.STL"/>
      </geometry>
      <material name="">
        <color rgba="0.752941176470588 0.752941176470588 0.752941176470588 1"/>
      </material>
    </visual>
    <!-- xyz="${0.0392698743200124} ${0.0120111889614487-0.095} ${0.0400984080168193-0.03}" /> -->
    <collision>     <!--collisionの記述をアクティブに変更-->
      <origin
        xyz="0 0 0"
        rpy="0 0 0" />
      <geometry>
        <mesh
          filename="meshes/grippers/six_fingered_gripper/base_gripper.STL" />
      </geometry>
    </collision>
  </link>
  <link name="gripper_finger_1">
    <inertial>
      <origin rpy="0 0 0" xyz="-0.0012619 0.038986 -2.3657E-12"/>
      <mass value="0.006157"/>
      <inertia ixx="2.4192E-06" ixy="2.4793E-07" ixz="2.8628E-15" iyy="1.6776E-07" iyz="1.1444E-15" izz="2.5199E-06"/>
    </inertial>
    <visual>
      <origin rpy="0 0 0" xyz="0 0 0"/>
      <geometry>
        <mesh filename="meshes/grippers/six_fingered_gripper/gripper_finger_1.STL"/>
      </geometry>
      <material name="">
        <color rgba="0.75294 0.75294 0.75294 1"/>
      </material>
    </visual>
    <collision>
      <origin
        xyz="0 0 0"
        rpy="0 0 0" />
      <geometry>
        <mesh
          filename="meshes/grippers/six_fingered_gripper/gripper_finger_1.STL" />
      </geometry>
    </collision>
  </link>
  <link name="gripper_finger_2">
    <inertial>
      <origin rpy="0 0 0" xyz="-0.0012619 0.038986 -2.3657E-12"/>
      <mass value="0.006157"/>
      <inertia ixx="2.4192E-06" ixy="2.4793E-07" ixz="2.8628E-15" iyy="1.6776E-07" iyz="1.1444E-15" izz="2.5199E-06"/>
    </inertial>
    <visual>
      <origin rpy="0 0 0" xyz="0 0 0"/>
      <geometry>
        <mesh filename="meshes/grippers/six_fingered_gripper/gripper_finger_2.STL"/>
      </geometry>
      <material name="">
        <color rgba="0.75294 0.75294 0.75294 1"/>
      </material>
    </visual>
    <collision>
      <origin
        xyz="0 0 0"
        rpy="0 0 0" />
      <geometry>
        <mesh
          filename="meshes/grippers/six_fingered_gripper/gripper_finger_2.STL" />
      </geometry>
    </collision>
  </link>
  <link name="gripper_finger_3">
    <inertial>
      <origin rpy="0 0 0" xyz="-0.0012619 0.038986 -2.3657E-12"/>
      <mass value="0.006157"/>
      <inertia ixx="2.4192E-06" ixy="2.4793E-07" ixz="2.8628E-15" iyy="1.6776E-07" iyz="1.1444E-15" izz="2.5199E-06"/>
    </inertial>
    <visual>
      <origin rpy="0 0 0" xyz="0 0 0"/>
      <geometry>
        <mesh filename="meshes/grippers/six_fingered_gripper/gripper_finger_3.STL"/>
      </geometry>
      <material name="">
        <color rgba="0.75294 0.75294 0.75294 1"/>
      </material>
    </visual>
    <collision>
      <origin
        xyz="0 0 0"
        rpy="0 0 0" />
      <geometry>
        <mesh
          filename="meshes/grippers/six_fingered_gripper/gripper_finger_3.STL" />
      </geometry>
    </collision>
  </link>
  <link name="gripper_finger_4">
    <inertial>
      <origin rpy="0 0 0" xyz="-0.00126191047827026 0.0389862430346049 -2.36565281253043E-12"/>
      <mass value="0.00615698496047359"/>
      <inertia ixx="2.41915556010585E-06" ixy="2.47931048420401E-07" ixz="2.86284769490924E-15" iyy="1.67755649991034E-07" iyz="1.14444598796065E-15" izz="2.51994852952969E-06"/>
    </inertial>
    <visual>
      <origin rpy="0 0 0" xyz="0 0 0"/>
      <geometry>
        <mesh filename="meshes/grippers/six_fingered_gripper/gripper_finger_4.STL"/>
      </geometry>
      <material name="">
        <color rgba="0.752941176470588 0.752941176470588 0.752941176470588 1"/>
      </material>
    </visual>
    <collision>
      <origin
        xyz="0 0 0"
        rpy="0 0 0" />
      <geometry>
        <mesh
          filename="meshes/grippers/six_fingered_gripper/gripper_finger_4.STL" />
      </geometry>
    </collision>
  </link>
  <link name="gripper_finger_5">
    <inertial>
      <origin rpy="0 0 0" xyz="-0.0012619 0.038986 -2.3657E-12"/>
      <mass value="0.006157"/>
      <inertia ixx="2.4192E-06" ixy="2.4793E-07" ixz="2.8628E-15" iyy="1.6776E-07" iyz="1.1444E-15" izz="2.5199E-06"/>
    </inertial>
    <visual>
      <origin rpy="0 0 0" xyz="0 0 0"/>
      <geometry>
        <mesh filename="meshes/grippers/six_fingered_gripper/gripper_finger_5.STL"/>
      </geometry>
      <material name="">
        <color rgba="0.75294 0.75294 0.75294 1"/>
      </material>
    </visual>
    <collision>
      <origin
        xyz="0 0 0"
        rpy="0 0 0" />
      <geometry>
        <mesh
          filename="meshes/grippers/six_fingered_gripper/gripper_finger_5.STL" />
      </geometry>
    </collision>
  </link>
  <link name="gripper_finger_6">
    <inertial>
      <origin rpy="0 0 0" xyz="-0.0012619 0.038986 -2.3657E-12"/>
      <mass value="0.006157"/>
      <inertia ixx="2.4192E-06" ixy="2.4793E-07" ixz="2.8628E-15" iyy="1.6776E-07" iyz="1.1444E-15" izz="2.5199E-06"/>
    </inertial>
    <visual>
      <origin rpy="0 0 0" xyz="0 0 0"/>
      <geometry>
        <mesh filename="meshes/grippers/six_fingered_gripper/gripper_finger_6.STL"/>
      </geometry>
      <material name="">
        <color rgba="0.75294 0.75294 0.75294 1"/>
      </material>
    </visual>
    <collision>
      <origin
        xyz="0 0 0"
        rpy="0 0 0" />
      <geometry>
        <mesh
          filename="meshes/grippers/six_fingered_gripper/gripper_finger_6.STL" />
      </geometry>
    </collision>
  </link>
  <!--ADDPOINT1END-->


  <joint name="joint1" type="revolute">
    <origin rpy="0 0 0" xyz="0 0 0.267"/>
    <parent link="link_base"/>
    <child link="link1"/>
    <axis xyz="0 0 1"/>
    <limit effort="50" lower="-6.28318530718" upper="6.28318530718" velocity="3.14"/>
    <dynamics damping="10" friction="1"/>
  </joint>
  <joint name="joint2" type="revolute">
    <origin rpy="-1.5708 0 0" xyz="0 0 0"/>
    <parent link="link1"/>
    <child link="link2"/>
    <axis xyz="0 0 1"/>
    <limit effort="50" lower="-2.059" upper="2.0944" velocity="3.14"/>
    <dynamics damping="10" friction="1"/>
  </joint>
  <joint name="joint3" type="revolute">
    <origin rpy="1.5708 0 0" xyz="0 -0.293 0"/>
    <parent link="link2"/>
    <child link="link3"/>
    <axis xyz="0 0 1"/>
    <limit effort="30" lower="-6.28318530718" upper="6.28318530718" velocity="3.14"/>
    <dynamics damping="5" friction="1"/>
  </joint>
  <joint name="joint4" type="revolute">
    <origin rpy="1.5708 0 0" xyz="0.0525 0 0"/>
    <parent link="link3"/>
    <child link="link4"/>
    <axis xyz="0 0 1"/>
    <limit effort="30" lower="-0.19198" upper="3.927" velocity="3.14"/>
    <dynamics damping="5" friction="1"/>
  </joint>
  <joint name="joint5" type="revolute">
    <origin rpy="1.5708 0 0" xyz="0.0775 -0.3425 0"/>
    <parent link="link4"/>
    <child link="link5"/>
    <axis xyz="0 0 1"/>
    <limit effort="30" lower="-6.28318530718" upper="6.28318530718" velocity="3.14"/>
    <dynamics damping="5" friction="1"/>
  </joint>
  <joint name="joint6" type="revolute">
    <origin rpy="1.5708 0 0" xyz="0 0 0"/>
    <parent link="link5"/>
    <child link="link6"/>
    <axis xyz="0 0 1"/>
    <limit effort="20" lower="-1.69297" upper="3.14159265359" velocity="3.14"/>
    <dynamics damping="2" friction="1"/>
  </joint>
  <joint name="joint7" type="revolute">
    <origin rpy="-1.5708 0 0" xyz="0.076 0.097 0"/>
    <parent link="link6"/>
    <child link="link7"/>
    <axis xyz="0 0 1"/>
    <limit effort="20" lower="-6.28318530718" upper="6.28318530718" velocity="3.14"/>
    <dynamics damping="2" friction="1"/>
  </joint>
  <!--ADDPOINT2START-->
  <joint name="joint_tool0" type="fixed">
    <origin rpy="-1.5708 0 1.5708" xyz="0 0 0"/>
    <!-- <origin rpy="0 0 0" xyz="0.34 0 0"/> -->
    <parent link="link7"/>
    <child link="tool0"/>
  </joint>
  <joint name="finger_joint_1" type="revolute">
    <origin rpy="0 1.0472 -3.1416" xyz="0.0175 -0.08 0.030311"/>
    <parent link="tool0"/>
    <child link="gripper_finger_1"/>
    <axis xyz="0 0 1"/>
    <limit
      lower="-0.25"
      upper="0"
      effort="0.7"
      velocity="3" />
  </joint>
  <joint name="finger_joint_2" type="revolute">
    <origin rpy="0 0 3.1416" xyz="0.035 -0.08 0"/>
    <parent link="tool0"/>
    <child link="gripper_finger_2"/>
    <axis xyz="0 0 1"/>
    <limit
      lower="-0.25"
      upper="0"
      effort="0.7"
      velocity="3" />
  </joint>
  <joint name="finger_joint_3" type="revolute">
    <origin rpy="0 -1.0472 3.1416" xyz="0.0175 -0.08 -0.030311"/>
    <parent link="tool0"/>
    <child link="gripper_finger_3"/>
    <axis xyz="0 0 1"/>
    <limit
      lower="-0.25"
      upper="0"
      effort="0.7"
      velocity="3" />
  </joint>
  <joint name="finger_joint_4" type="revolute">
    <origin rpy="3.1416 -1.0472 0" xyz="-0.0175 -0.08 -0.030311"/>
    <parent link="tool0"/>
    <child link="gripper_finger_4"/>
    <axis xyz="0 0 1"/>
    <limit
      lower="-0.25"
      upper="0"
      effort="0.7"
      velocity="3" />
  </joint>
  <joint name="finger_joint_5" type="revolute">
    <origin rpy="3.1416 0 0" xyz="-0.035 -0.08 0"/>
    <parent link="tool0"/>
    <child link="gripper_finger_5"/>
    <axis xyz="0 0 1"/>
    <limit
      lower="-0.25"
      upper="0"
      effort="0.7"
      velocity="3" />
  </joint>
  <joint name="finger_joint_6" type="revolute">
    <origin rpy="3.1416 1.0472 0" xyz="-0.0175 -0.08 0.030311"/>
    <parent link="tool0"/>
    <child link="gripper_finger_6"/>
    <axis xyz="0 0 1"/>
    <limit
      lower="-0.25"
      upper="0"
      effort="0.7"
      velocity="3" />
  </joint>
  <!--ADDPOINT2END-->

  <transmission name="tran1">
    <type>transmission_interface/SimpleTransmission</type>
    <joint name="joint1">
      <hardwareInterface>hardware_interface/PositionJointInterface</hardwareInterface>
    </joint>
    <actuator name="motor1">
      <hardwareInterface>hardware_interface/PositionJointInterface</hardwareInterface>
      <mechanicalReduction>100</mechanicalReduction>
    </actuator>
  </transmission>
  <transmission name="tran2">
    <type>transmission_interface/SimpleTransmission</type>
    <joint name="joint2">
      <hardwareInterface>hardware_interface/PositionJointInterface</hardwareInterface>
    </joint>
    <actuator name="motor2">
      <hardwareInterface>hardware_interface/PositionJointInterface</hardwareInterface>
      <mechanicalReduction>reduction</mechanicalReduction>
    </actuator>
  </transmission>
  <transmission name="tran3">
    <type>transmission_interface/SimpleTransmission</type>
    <joint name="joint3">
      <hardwareInterface>hardware_interface/PositionJointInterface</hardwareInterface>
    </joint>
    <actuator name="motor3">
      <hardwareInterface>hardware_interface/PositionJointInterface</hardwareInterface>
      <mechanicalReduction>reduction</mechanicalReduction>
    </actuator>
  </transmission>
  <transmission name="tran4">
    <type>transmission_interface/SimpleTransmission</type>
    <joint name="joint4">
      <hardwareInterface>hardware_interface/PositionJointInterface</hardwareInterface>
    </joint>
    <actuator name="motor4">
      <hardwareInterface>hardware_interface/PositionJointInterface</hardwareInterface>
      <mechanicalReduction>reduction</mechanicalReduction>
    </actuator>
  </transmission>
  <transmission name="tran5">
    <type>transmission_interface/SimpleTransmission</type>
    <joint name="joint5">
      <hardwareInterface>hardware_interface/PositionJointInterface</hardwareInterface>
    </joint>
    <actuator name="motor5">
      <hardwareInterface>hardware_interface/PositionJointInterface</hardwareInterface>
      <mechanicalReduction>reduction</mechanicalReduction>
    </actuator>
  </transmission>
  <transmission name="tran6">
    <type>transmission_interface/SimpleTransmission</type>
    <joint name="joint6">
      <hardwareInterface>hardware_interface/PositionJointInterface</hardwareInterface>
    </joint>
    <actuator name="motor6">
      <hardwareInterface>hardware_interface/PositionJointInterface</hardwareInterface>
      <mechanicalReduction>reduction</mechanicalReduction>
    </actuator>
  </transmission>
  <transmission name="tran7">
    <type>transmission_interface/SimpleTransmission</type>
    <joint name="joint7">
      <hardwareInterface>hardware_interface/PositionJointInterface</hardwareInterface>
    </joint>
    <actuator name="motor7">
      <hardwareInterface>hardware_interface/PositionJointInterface</hardwareInterface>
      <mechanicalReduction>reduction</mechanicalReduction>
    </actuator>
  </transmission>
  <!--ADPOINT3START-->
  <transmission name="transmission_1">
    <type>transmission_interface/SimpleTransmission</type>
    <joint name="finger_joint_1">
      <hardwareInterface>PositionJointInterface</hardwareInterface>
   </joint>
    <actuator name="motor_1">
      <hardwareInterface>PositionJointInterface</hardwareInterface>
      <mechanicalReduction>10</mechanicalReduction>
    </actuator>
  </transmission>
  <transmission name="transmission_2">
    <type>transmission_interface/SimpleTransmission</type>
    <joint name="finger_joint_2">
      <hardwareInterface>PositionJointInterface</hardwareInterface>
   </joint>
    <actuator name="motor_2">
      <hardwareInterface>PositionJointInterface</hardwareInterface>
      <mechanicalReduction>10</mechanicalReduction>
    </actuator>
  </transmission>  <transmission name="transmission_3">
    <type>transmission_interface/SimpleTransmission</type>
    <joint name="finger_joint_3">
      <hardwareInterface>PositionJointInterface</hardwareInterface>
   </joint>
    <actuator name="motor_3">
      <hardwareInterface>PositionJointInterface</hardwareInterface>
      <mechanicalReduction>10</mechanicalReduction>
    </actuator>
  </transmission>  <transmission name="transmission_4">
    <type>transmission_interface/SimpleTransmission</type>
    <joint name="finger_joint_4">
      <hardwareInterface>PositionJointInterface</hardwareInterface>
   </joint>
    <actuator name="motor_4">
      <hardwareInterface>PositionJointInterface</hardwareInterface>
      <mechanicalReduction>10</mechanicalReduction>
    </actuator>
  </transmission>  <transmission name="transmission_5">
    <type>transmission_interface/SimpleTransmission</type>
    <joint name="finger_joint_5">
      <hardwareInterface>PositionJointInterface</hardwareInterface>
   </joint>
    <actuator name="motor_5">
      <hardwareInterface>PositionJointInterface</hardwareInterface>
      <mechanicalReduction>10</mechanicalReduction>
    </actuator>
  </transmission>  <transmission name="transmission_6">
    <type>transmission_interface/SimpleTransmission</type>
    <joint name="finger_joint_6">
      <hardwareInterface>PositionJointInterface</hardwareInterface>
   </joint>
    <actuator name="motor_6">
      <hardwareInterface>PositionJointInterface</hardwareInterface>
      <mechanicalReduction>10</mechanicalReduction>
    </actuator>
  </transmission>
  <!--ADDPOINT3END-->

  <!-- gazebo -->
  <gazebo>
    <plugin filename="libgazebo_ros_control.so" name="gazebo_ros_control">
      <robotNamespace>/xarm</robotNamespace>
      <!-- <controlPeriod>0.0001</controlPeriod> -->
      <robotSimType>gazebo_ros_control/DefaultRobotHWSim</robotSimType>
      <legacyModeNS>true</legacyModeNS>
      <!-- <preserveWorldVelocity>true</preserveWorldVelocity> -->
    </plugin>
  </gazebo>
  <gazebo reference="link_base">
    <selfCollide>true</selfCollide>
  </gazebo>
  <gazebo reference="link1">
    <selfCollide>true</selfCollide>
  </gazebo>
  <gazebo reference="link2">
    <selfCollide>true</selfCollide>
  </gazebo>
  <gazebo reference="link3">
    <selfCollide>true</selfCollide>
  </gazebo>
  <gazebo reference="link4">
    <selfCollide>true</selfCollide>
  </gazebo>
  <gazebo reference="link5">
    <selfCollide>true</selfCollide>
  </gazebo>
  <gazebo reference="link6">
    <selfCollide>true</selfCollide>
  </gazebo>
  <gazebo reference="link7">
    <selfCollide>true</selfCollide>
  </gazebo>
  
  <!--ADDPOINT4START-->
  <gazebo reference="gripper_finger_1">
    <mu1>0.2</mu1>
    <mu2>0.2</mu2>
    <selfCollide>true</selfCollide>
  </gazebo>
  <gazebo reference="gripper_finger_2">
    <mu1>0.2</mu1>
    <mu2>0.2</mu2>
    <selfCollide>true</selfCollide>
  </gazebo>
  <gazebo reference="gripper_finger_3">
    <mu1>0.2</mu1>
    <mu2>0.2</mu2>
    <selfCollide>true</selfCollide>
  </gazebo>
  <gazebo reference="gripper_finger_4">
    <mu1>0.2</mu1>
    <mu2>0.2</mu2>
    <selfCollide>true</selfCollide>
  </gazebo>
  <gazebo reference="gripper_finger_5">
    <mu1>0.2</mu1>
    <mu2>0.2</mu2>
    <selfCollide>true</selfCollide>
  </gazebo>
  <gazebo reference="gripper_finger_6">
    <mu1>0.2</mu1>
    <mu2>0.2</mu2>
    <selfCollide>true</selfCollide>
  </gazebo>
  <!--ADDPOINT4END-->
  <link name="world"/>
  <joint name="world" type="fixed">
    <origin rpy="0 0 0" xyz="0 0 0.2"/>
    <parent link="world"/>
    <child link="link_base"/>
  </joint>
  <link name="eef_link"/>
  <joint name="tool0_ee_joint" type="fixed">
    <origin rpy="4.71238898038469 0 -1.5707963267948966" xyz="0.0 0 0"/>
    <!-- eef is at the center of gripper-->
    <parent link="tool0"/>
    <child link="eef_link"/>
  </joint>
  <link name="xarm7_base">
    <visual>
      <geometry>
        <mesh filename="meshes/motoman_base/motoman_base.stl" scale="1 1 1"/>
      </geometry>
      <origin rpy="1.5707963267948966 0 1.5707963267948966" xyz="0 0 0"/>
      <material name="Green">
        <color rgba="0 1 0 0.5"/>
      </material>
    </visual>
    <collision>
      <geometry>
        <mesh filename="meshes/motoman_base/motoman_base.stl" scale="1 1 1"/>
      </geometry>
      <origin rpy="1.5707963267948966 0 1.5707963267948966" xyz="0 0 0"/>
    </collision>
  </link>
  <joint name="xarm7_base_to_world" type="fixed">
    <parent link="world"/>
    <child link="xarm7_base"/>
    <origin rpy="0 0 0" xyz="0.55 0.33 -0.5"/>
  </joint>
</robot>
