<?xml version="1.0" ?>
<!-- =================================================================================== -->
<!-- |    This document was autogenerated by xacro from sia5_basic.urdf.xacro          | -->
<!-- |    EDITING THIS FILE BY HAND IS NOT RECOMMENDED                                 | -->
<!-- =================================================================================== -->
<robot name="sia5">
  <material name="black">
    <color rgba="0.0 0.0 0.0 1.0"/>
  </material>
  <material name="blue">
    <color rgba="0.0 0.0 0.8 1.0"/>
  </material>
  <material name="green">
    <color rgba="0.0 0.8 0.0 1.0"/>
  </material>
  <material name="grey">
    <color rgba="0.2 0.2 0.2 1.0"/>
  </material>
  <material name="orange">
    <color rgba="1.0 0.4235294117647059 0.0392156862745098 1.0"/>
  </material>
  <material name="brown">
    <color rgba="0.8705882352941177 0.8117647058823529 0.7647058823529411 1.0"/>
  </material>
  <material name="red">
    <color rgba="0.8 0.0 0.0 1.0"/>
  </material>
  <material name="white">
    <color rgba="1.0 1.0 1.0 1.0"/>
  </material>
  <link name="base_link">
    <visual>
      <geometry>
        <mesh filename="package://motoman_description/meshes/sia5/visual/COLLADA/base_link.dae"/>
      </geometry>
    </visual>
    <collision>
      <geometry>
        <mesh filename="package://motoman_description/meshes/sia5/collision/STL/base_link.stl"/>
      </geometry>
    </collision>
    <inertial>
      <origin rpy="0 0 0" xyz="-0.025918 -0.000376 0.076105"/>
      <mass value="9.23913043478261"/>
      <inertia ixx="0.03786850090579711" ixy="0" ixz="0" iyy="0.0465867830615942" iyz="0" izz="0.0514065294384058"/>
    </inertial>
  </link>
  <link name="link_s">
    <visual>
      <geometry>
        <mesh filename="package://motoman_description/meshes/sia5/visual/COLLADA/link_s.dae"/>
      </geometry>
    </visual>
    <collision>
      <geometry>
        <mesh filename="package://motoman_description/meshes/sia5/collision/STL/link_s.stl"/>
      </geometry>
    </collision>
    <inertial>
      <origin rpy="0 0 0" xyz="0 0 0"/>
      <mass value="8.369565217391305"/>
      <inertia ixx="0.12852840000000001" ixy="0" ixz="0" iyy="0.12769725195652173" iyz="0" izz="0.018662367246376814"/>
    </inertial>
  </link>
  <link name="link_l">
    <visual>
      <geometry>
        <mesh filename="package://motoman_description/meshes/sia5/visual/COLLADA/link_l.dae"/>
      </geometry>
    </visual>
    <collision>
      <geometry>
        <mesh filename="package://motoman_description/meshes/sia5/collision/STL/link_l.stl"/>
      </geometry>
    </collision>
    <inertial>
      <origin rpy="3.14159274 0 0" xyz="0 -0.006 0.15"/>
      <mass value="7.608695652173914"/>
      <inertia ixx="0.12248884057971018" ixy="0" ixz="0" iyy="0.11755461666666668" iyz="0" izz="0.017749580434782614"/>
    </inertial>
  </link>
  <link name="link_e">
    <visual>
      <geometry>
        <mesh filename="package://motoman_description/meshes/sia5/visual/COLLADA/link_e.dae"/>
      </geometry>
    </visual>
    <collision>
      <geometry>
        <mesh filename="package://motoman_description/meshes/sia5/collision/STL/link_e.stl"/>
      </geometry>
    </collision>
    <inertial>
      <origin rpy="0 0 -1.57079637" xyz="0 0 0"/>
      <mass value="1.3043478260869565"/>
      <inertia ixx="0.012289938173913044" ixy="0" ixz="0" iyy="0.011712778782608698" iyz="0" izz="0.003444012347826088"/>
    </inertial>
  </link>
  <link name="link_u">
    <visual>
      <geometry>
        <mesh filename="package://motoman_description/meshes/sia5/visual/COLLADA/link_u.dae"/>
      </geometry>
    </visual>
    <collision>
      <geometry>
        <mesh filename="package://motoman_description/meshes/sia5/collision/STL/link_u.stl"/>
      </geometry>
    </collision>
    <inertial>
      <origin rpy="-3.14159274 1.57079637 0" xyz="0.008 -0.06 -0.131"/>
      <mass value="1.0869565217391304"/>
      <inertia ixx="0.011020711576811592" ixy="0" ixz="0" iyy="0.009968035942028984" iyz="0" izz="0.0021404385333333316"/>
    </inertial>
  </link>
  <link name="link_r">
    <visual>
      <geometry>
        <mesh filename="package://motoman_description/meshes/sia5/visual/COLLADA/link_r.dae"/>
      </geometry>
    </visual>
    <collision>
      <geometry>
        <mesh filename="package://motoman_description/meshes/sia5/collision/STL/link_r.stl"/>
      </geometry>
    </collision>
    <inertial>
      <origin rpy="0 0 -1.57079637" xyz="0 0 0"/>
      <mass value="0.9782608695652175"/>
      <inertia ixx="0.010840083220108696" ixy="0" ixz="0" iyy="0.01070887398097826" iyz="0" izz="0.0014045686141304344"/>
    </inertial>
  </link>
  <link name="link_b">
    <visual>
      <geometry>
        <mesh filename="package://motoman_description/meshes/sia5/visual/COLLADA/link_b.dae"/>
      </geometry>
    </visual>
    <collision>
      <geometry>
        <mesh filename="package://motoman_description/meshes/sia5/collision/STL/link_b.stl"/>
      </geometry>
    </collision>
    <inertial>
      <origin rpy="1.57079637 -1.57079637 0" xyz="0 0.0045 0.1365"/>
      <mass value="0.8695652173913044"/>
      <inertia ixx="0.008143418695652176" ixy="0" ixz="0" iyy="0.007094738695652175" iyz="0" izz="0.0007365773913043478"/>
    </inertial>
  </link>
  <link name="link_t">
    <visual>
      <geometry>
        <mesh filename="package://motoman_description/meshes/sia5/visual/COLLADA/link_t.dae"/>
      </geometry>
    </visual>
    <collision>
      <geometry>
        <mesh filename="package://motoman_description/meshes/sia5/collision/STL/link_t.stl"/>
      </geometry>
    </collision>
    <inertial>
      <mass value="0.5434782608695652"/>
      <inertia ixx="0.003" ixy="0" ixz="0" iyy="0.003" iyz="0" izz="0.001"/>
    </inertial>
  </link>
  <!--<link name="tool0"/>-->
  <!--ADDPOINT1START-->
  <link name="tool0">
    <inertial>
      <origin rpy="0 0 0" xyz="1.10509452800074E-06 0.00208243198225818 0.0400984076446437"/>
      <mass value="0.185199260372416"/>
      <inertia ixx="9.76222430788153E-05" ixy="-7.8112390093605E-09" ixz="6.20208431775755E-12" iyy="8.20988447730316E-05" iyz="-3.40692325998543E-06" izz="0.000149625833719171"/>
    </inertial>
    <visual>
      <origin rpy="0 0 0" xyz="0 0 0"/>
      <geometry>
        <mesh filename="package://motoman_description/meshes/grippers/six_fingered_gripper/base_gripper.STL"/>
      </geometry>
      <material name="">
        <color rgba="0.752941176470588 0.752941176470588 0.752941176470588 1"/>
      </material>
    </visual>
    <!-- xyz="${0.0392698743200124} ${0.0120111889614487-0.095} ${0.0400984080168193-0.03}" /> -->
    <collision>     <!--collisionの記述をアクティブに変更-->
      <origin
        xyz="0 0 0"
        rpy="0 0 0" />
      <geometry>
        <mesh
          filename="package://motoman_description/meshes/grippers/six_fingered_gripper/base_gripper.STL" />
      </geometry>
    </collision>
  </link>
  <link name="gripper_finger_1">
    <inertial>
      <origin rpy="0 0 0" xyz="-0.0012619 0.038986 -2.3657E-12"/>
      <mass value="0.006157"/>
      <inertia ixx="2.4192E-06" ixy="2.4793E-07" ixz="2.8628E-15" iyy="1.6776E-07" iyz="1.1444E-15" izz="2.5199E-06"/>
    </inertial>
    <visual>
      <origin rpy="0 0 0" xyz="0 0 0"/>
      <geometry>
        <mesh filename="package://motoman_description/meshes/grippers/six_fingered_gripper/gripper_finger_1.STL"/>
      </geometry>
      <material name="">
        <color rgba="0.75294 0.75294 0.75294 1"/>
      </material>
    </visual>
    <collision>
      <origin
        xyz="0 0 0"
        rpy="0 0 0" />
      <geometry>
        <mesh
          filename="package://motoman_description/meshes/grippers/six_fingered_gripper/gripper_finger_1.STL" />
      </geometry>
    </collision>
  </link>
  <link name="gripper_finger_2">
    <inertial>
      <origin rpy="0 0 0" xyz="-0.0012619 0.038986 -2.3657E-12"/>
      <mass value="0.006157"/>
      <inertia ixx="2.4192E-06" ixy="2.4793E-07" ixz="2.8628E-15" iyy="1.6776E-07" iyz="1.1444E-15" izz="2.5199E-06"/>
    </inertial>
    <visual>
      <origin rpy="0 0 0" xyz="0 0 0"/>
      <geometry>
        <mesh filename="package://motoman_description/meshes/grippers/six_fingered_gripper/gripper_finger_2.STL"/>
      </geometry>
      <material name="">
        <color rgba="0.75294 0.75294 0.75294 1"/>
      </material>
    </visual>
    <collision>
      <origin
        xyz="0 0 0"
        rpy="0 0 0" />
      <geometry>
        <mesh
          filename="package://motoman_description/meshes/grippers/six_fingered_gripper/gripper_finger_2.STL" />
      </geometry>
    </collision>
  </link>
  <link name="gripper_finger_3">
    <inertial>
      <origin rpy="0 0 0" xyz="-0.0012619 0.038986 -2.3657E-12"/>
      <mass value="0.006157"/>
      <inertia ixx="2.4192E-06" ixy="2.4793E-07" ixz="2.8628E-15" iyy="1.6776E-07" iyz="1.1444E-15" izz="2.5199E-06"/>
    </inertial>
    <visual>
      <origin rpy="0 0 0" xyz="0 0 0"/>
      <geometry>
        <mesh filename="package://motoman_description/meshes/grippers/six_fingered_gripper/gripper_finger_3.STL"/>
      </geometry>
      <material name="">
        <color rgba="0.75294 0.75294 0.75294 1"/>
      </material>
    </visual>
    <collision>
      <origin
        xyz="0 0 0"
        rpy="0 0 0" />
      <geometry>
        <mesh
          filename="package://motoman_description/meshes/grippers/six_fingered_gripper/gripper_finger_3.STL" />
      </geometry>
    </collision>
  </link>
  <link name="gripper_finger_4">
    <inertial>
      <origin rpy="0 0 0" xyz="-0.00126191047827026 0.0389862430346049 -2.36565281253043E-12"/>
      <mass value="0.00615698496047359"/>
      <inertia ixx="2.41915556010585E-06" ixy="2.47931048420401E-07" ixz="2.86284769490924E-15" iyy="1.67755649991034E-07" iyz="1.14444598796065E-15" izz="2.51994852952969E-06"/>
    </inertial>
    <visual>
      <origin rpy="0 0 0" xyz="0 0 0"/>
      <geometry>
        <mesh filename="package://motoman_description/meshes/grippers/six_fingered_gripper/gripper_finger_4.STL"/>
      </geometry>
      <material name="">
        <color rgba="0.752941176470588 0.752941176470588 0.752941176470588 1"/>
      </material>
    </visual>
    <collision>
      <origin
        xyz="0 0 0"
        rpy="0 0 0" />
      <geometry>
        <mesh
          filename="package://motoman_description/meshes/grippers/six_fingered_gripper/gripper_finger_4.STL" />
      </geometry>
    </collision>
  </link>
  <link name="gripper_finger_5">
    <inertial>
      <origin rpy="0 0 0" xyz="-0.0012619 0.038986 -2.3657E-12"/>
      <mass value="0.006157"/>
      <inertia ixx="2.4192E-06" ixy="2.4793E-07" ixz="2.8628E-15" iyy="1.6776E-07" iyz="1.1444E-15" izz="2.5199E-06"/>
    </inertial>
    <visual>
      <origin rpy="0 0 0" xyz="0 0 0"/>
      <geometry>
        <mesh filename="package://motoman_description/meshes/grippers/six_fingered_gripper/gripper_finger_5.STL"/>
      </geometry>
      <material name="">
        <color rgba="0.75294 0.75294 0.75294 1"/>
      </material>
    </visual>
    <collision>
      <origin
        xyz="0 0 0"
        rpy="0 0 0" />
      <geometry>
        <mesh
          filename="package://motoman_description/meshes/grippers/six_fingered_gripper/gripper_finger_5.STL" />
      </geometry>
    </collision>
  </link>
  <link name="gripper_finger_6">
    <inertial>
      <origin rpy="0 0 0" xyz="-0.0012619 0.038986 -2.3657E-12"/>
      <mass value="0.006157"/>
      <inertia ixx="2.4192E-06" ixy="2.4793E-07" ixz="2.8628E-15" iyy="1.6776E-07" iyz="1.1444E-15" izz="2.5199E-06"/>
    </inertial>
    <visual>
      <origin rpy="0 0 0" xyz="0 0 0"/>
      <geometry>
        <mesh filename="package://motoman_description/meshes/grippers/six_fingered_gripper/gripper_finger_6.STL"/>
      </geometry>
      <material name="">
        <color rgba="0.75294 0.75294 0.75294 1"/>
      </material>
    </visual>
    <collision>
      <origin
        xyz="0 0 0"
        rpy="0 0 0" />
      <geometry>
        <mesh
          filename="package://motoman_description/meshes/grippers/six_fingered_gripper/gripper_finger_6.STL" />
      </geometry>
    </collision>
  </link>
  <!--ADDPOINT1END-->

  
  <joint name="joint_s" type="revolute">
    <origin rpy="0 0 0" xyz="0 0 0.1765"/>
    <parent link="base_link"/>
    <child link="link_s"/>
    <axis xyz="0 0 1"/>
    <dynamics damping="0.7" friction="0.7"/>
    <limit effort="30.0" lower="-2.984512937193716" upper="2.984512937193716" velocity="3.3161256699999995"/>
  </joint>
  <joint name="joint_l" type="revolute">
    <origin rpy="0 0 0" xyz="0 0.006 0.136"/>
    <parent link="link_s"/>
    <child link="link_l"/>
    <axis xyz="0 1 0"/>
    <dynamics damping="0.7" friction="0.7"/>
    <limit effort="30.0" lower="-1.8238691185" upper="1.8238691185" velocity="3.3161256699999995"/>
  </joint>
  <joint name="joint_e" type="revolute">
    <origin rpy="0 0 0" xyz="0 -0.006 0.15"/>
    <parent link="link_l"/>
    <child link="link_e"/>
    <axis xyz="0 0 1"/>
    <dynamics damping="0.7" friction="0.7"/>
    <limit effort="30.0" lower="-2.8187068194999996" upper="2.8187068194999996" velocity="3.3161256699999995"/>
  </joint>
  <joint name="joint_u" type="revolute">
    <origin rpy="1.57079637 0 0" xyz="0.085 -0.00826931 0.12275299"/>
    <parent link="link_e"/>
    <child link="link_u"/>
    <axis xyz="0 0 1"/>
    <dynamics damping="0.7" friction="0.7"/>
    <limit effort="30.0" lower="-1.4922565515" upper="1.90677226025" velocity="3.3161256699999995"/>
  </joint>
  <joint name="joint_r" type="revolute">
    <origin rpy="0 1.57079637 0" xyz="0.131 0.06 -0.008"/>
    <parent link="link_u"/>
    <child link="link_r"/>
    <axis xyz="0 0 -1"/>
    <dynamics damping="0.7" friction="0.7"/>
    <limit effort="14.7" lower="-2.984512937193716" upper="2.984512937193716" velocity="3.3161256699999995"/>
  </joint>
  <joint name="joint_b" type="revolute">
    <origin rpy="0 -1.57079637 0" xyz="-0.0045 0 0.139"/>
    <parent link="link_r"/>
    <child link="link_b"/>
    <axis xyz="0 0 1"/>
    <dynamics damping="0.7" friction="0.7"/>
    <limit effort="14.7" lower="-1.8238691185" upper="1.8238691185" velocity="3.8135445205"/>
  </joint>
  <joint name="joint_t" type="revolute">
    <origin rpy="-1.57079637 0 0" xyz="0.1365 0 -0.0045"/>
    <parent link="link_b"/>
    <child link="link_t"/>
    <axis xyz="-1 0 0"/>
    <dynamics damping="0.7" friction="0.7"/>
    <limit effort="7.35" lower="-2.984512937193716" upper="2.984512937193716" velocity="5.8032199225"/>
  </joint>
  <joint name="joint_tool0" type="fixed">
    <origin rpy="0 0 1.5708" xyz="0.0115 0 0"/>
    <!-- <origin rpy="0 0 0" xyz="0.34 0 0"/> -->
    <parent link="link_t"/>
    <child link="tool0"/>
  </joint>
  <!--ADDPOINT2START-->
  <joint name="finger_joint_1" type="revolute">
    <origin rpy="0 1.0472 -3.1416" xyz="0.0175 -0.08 0.030311"/>
    <parent link="tool0"/>
    <child link="gripper_finger_1"/>
    <axis xyz="0 0 1"/>
    <limit
      lower="-0.25"
      upper="0"
      effort="0.7"
      velocity="3" />
  </joint>
  <joint name="finger_joint_2" type="revolute">
    <origin rpy="0 0 3.1416" xyz="0.035 -0.08 0"/>
    <parent link="tool0"/>
    <child link="gripper_finger_2"/>
    <axis xyz="0 0 1"/>
    <limit
      lower="-0.25"
      upper="0"
      effort="0.7"
      velocity="3" />
  </joint>
  <joint name="finger_joint_3" type="revolute">
    <origin rpy="0 -1.0472 3.1416" xyz="0.0175 -0.08 -0.030311"/>
    <parent link="tool0"/>
    <child link="gripper_finger_3"/>
    <axis xyz="0 0 1"/>
    <limit
      lower="-0.25"
      upper="0"
      effort="0.7"
      velocity="3" />
  </joint>
  <joint name="finger_joint_4" type="revolute">
    <origin rpy="3.1416 -1.0472 0" xyz="-0.0175 -0.08 -0.030311"/>
    <parent link="tool0"/>
    <child link="gripper_finger_4"/>
    <axis xyz="0 0 1"/>
    <limit
      lower="-0.25"
      upper="0"
      effort="0.7"
      velocity="3" />
  </joint>
  <joint name="finger_joint_5" type="revolute">
    <origin rpy="3.1416 0 0" xyz="-0.035 -0.08 0"/>
    <parent link="tool0"/>
    <child link="gripper_finger_5"/>
    <axis xyz="0 0 1"/>
    <limit
      lower="-0.25"
      upper="0"
      effort="0.7"
      velocity="3" />
  </joint>
  <joint name="finger_joint_6" type="revolute">
    <origin rpy="3.1416 1.0472 0" xyz="-0.0175 -0.08 0.030311"/>
    <parent link="tool0"/>
    <child link="gripper_finger_6"/>
    <axis xyz="0 0 1"/>
    <limit
      lower="-0.25"
      upper="0"
      effort="0.7"
      velocity="3" />
  </joint>
  <!--ADDPOINT2END-->


  <transmission name="transmission_s">
    <type>transmission_interface/SimpleTransmission</type>
    <joint name="joint_s">
      <hardwareInterface>PositionJointInterface</hardwareInterface>
    </joint>
    <actuator name="motor_s">
      <hardwareInterface>PositionJointInterface</hardwareInterface>
      <mechanicalReduction>300</mechanicalReduction>
    </actuator>
  </transmission>
  <transmission name="transmission_l">
    <type>transmission_interface/SimpleTransmission</type>
    <joint name="joint_l">
      <hardwareInterface>PositionJointInterface</hardwareInterface>
    </joint>
    <actuator name="motor_l">
      <hardwareInterface>PositionJointInterface</hardwareInterface>
      <mechanicalReduction>300</mechanicalReduction>
    </actuator>
  </transmission>
  <transmission name="transmission_e">
    <type>transmission_interface/SimpleTransmission</type>
    <joint name="joint_e">
      <hardwareInterface>PositionJointInterface</hardwareInterface>
    </joint>
    <actuator name="motor_e">
      <hardwareInterface>PositionJointInterface</hardwareInterface>
      <mechanicalReduction>100</mechanicalReduction>
    </actuator>
  </transmission>
  <transmission name="transmission_u">
    <type>transmission_interface/SimpleTransmission</type>
    <joint name="joint_u">
      <hardwareInterface>PositionJointInterface</hardwareInterface>
    </joint>
    <actuator name="motor_u">
      <hardwareInterface>PositionJointInterface</hardwareInterface>
      <mechanicalReduction>50</mechanicalReduction>
    </actuator>
  </transmission>
  <transmission name="transmission_r">
    <type>transmission_interface/SimpleTransmission</type>
    <joint name="joint_r">
      <hardwareInterface>PositionJointInterface</hardwareInterface>
    </joint>
    <actuator name="motor_r">
      <hardwareInterface>PositionJointInterface</hardwareInterface>
      <mechanicalReduction>30</mechanicalReduction>
    </actuator>
  </transmission>
  <transmission name="transmission_b">
    <type>transmission_interface/SimpleTransmission</type>
    <joint name="joint_b">
      <hardwareInterface>PositionJointInterface</hardwareInterface>
    </joint>
    <actuator name="motor_b">
      <hardwareInterface>PositionJointInterface</hardwareInterface>
      <mechanicalReduction>30</mechanicalReduction>
    </actuator>
  </transmission>
  <transmission name="transmission_t">
    <type>transmission_interface/SimpleTransmission</type>
    <joint name="joint_t">
      <hardwareInterface>PositionJointInterface</hardwareInterface>
    </joint>
    <actuator name="motor_t">
      <hardwareInterface>PositionJointInterface</hardwareInterface>
      <mechanicalReduction>10</mechanicalReduction>
    </actuator>
  </transmission>

  <!--ADPOINT3START-->
  <transmission name="transmission_1">
    <type>transmission_interface/SimpleTransmission</type>
    <joint name="finger_joint_1">
      <hardwareInterface>PositionJointInterface</hardwareInterface>
   </joint>
    <actuator name="motor_1">
      <hardwareInterface>PositionJointInterface</hardwareInterface>
      <mechanicalReduction>10</mechanicalReduction>
    </actuator>
  </transmission>
  <transmission name="transmission_2">
    <type>transmission_interface/SimpleTransmission</type>
    <joint name="finger_joint_2">
      <hardwareInterface>PositionJointInterface</hardwareInterface>
   </joint>
    <actuator name="motor_2">
      <hardwareInterface>PositionJointInterface</hardwareInterface>
      <mechanicalReduction>10</mechanicalReduction>
    </actuator>
  </transmission>  <transmission name="transmission_3">
    <type>transmission_interface/SimpleTransmission</type>
    <joint name="finger_joint_3">
      <hardwareInterface>PositionJointInterface</hardwareInterface>
   </joint>
    <actuator name="motor_3">
      <hardwareInterface>PositionJointInterface</hardwareInterface>
      <mechanicalReduction>10</mechanicalReduction>
    </actuator>
  </transmission>  <transmission name="transmission_4">
    <type>transmission_interface/SimpleTransmission</type>
    <joint name="finger_joint_4">
      <hardwareInterface>PositionJointInterface</hardwareInterface>
   </joint>
    <actuator name="motor_4">
      <hardwareInterface>PositionJointInterface</hardwareInterface>
      <mechanicalReduction>10</mechanicalReduction>
    </actuator>
  </transmission>  <transmission name="transmission_5">
    <type>transmission_interface/SimpleTransmission</type>
    <joint name="finger_joint_5">
      <hardwareInterface>PositionJointInterface</hardwareInterface>
   </joint>
    <actuator name="motor_5">
      <hardwareInterface>PositionJointInterface</hardwareInterface>
      <mechanicalReduction>10</mechanicalReduction>
    </actuator>
  </transmission>  <transmission name="transmission_6">
    <type>transmission_interface/SimpleTransmission</type>
    <joint name="finger_joint_6">
      <hardwareInterface>PositionJointInterface</hardwareInterface>
   </joint>
    <actuator name="motor_6">
      <hardwareInterface>PositionJointInterface</hardwareInterface>
      <mechanicalReduction>10</mechanicalReduction>
    </actuator>
  </transmission>
  <!--ADDPOINT3END-->

  <!-- gazebo -->
  <gazebo>
    <plugin filename="libgazebo_ros_control.so" name="gazebo_ros_control">
      <robotSimType>gazebo_ros_control/DefaultRobotHWSim</robotSimType>
    </plugin>
  </gazebo>
  <gazebo reference="base_link">
    <mu1>0.2</mu1>
    <mu2>0.2</mu2>
    <selfCollide>true</selfCollide>
  </gazebo>
  <gazebo reference="link_s">
    <mu1>0.2</mu1>
    <mu2>0.2</mu2>
    <selfCollide>true</selfCollide>
  </gazebo>
  <gazebo reference="link_l">
    <mu1>0.2</mu1>
    <mu2>0.2</mu2>
    <selfCollide>true</selfCollide>
  </gazebo>
  <gazebo reference="link_e">
    <mu1>0.2</mu1>
    <mu2>0.2</mu2>
    <selfCollide>true</selfCollide>
  </gazebo>
  <gazebo reference="link_u">
    <mu1>0.2</mu1>
    <mu2>0.2</mu2>
    <selfCollide>true</selfCollide>
  </gazebo>
  <gazebo reference="link_r">
    <mu1>0.2</mu1>
    <mu2>0.2</mu2>
    <selfCollide>true</selfCollide>
  </gazebo>
  <gazebo reference="link_b">
    <mu1>0.2</mu1>
    <mu2>0.2</mu2>
    <selfCollide>true</selfCollide>
  </gazebo>
  <gazebo reference="link_t">
    <mu1>0.2</mu1>
    <mu2>0.2</mu2>
    <selfCollide>true</selfCollide>
  </gazebo>

  <!--ADDPOINT4START-->
    <gazebo reference="gripper_finger_1">
    <mu1>0.2</mu1>
    <mu2>0.2</mu2>
    <selfCollide>true</selfCollide>
  </gazebo>
  <gazebo reference="gripper_finger_2">
    <mu1>0.2</mu1>
    <mu2>0.2</mu2>
    <selfCollide>true</selfCollide>
  </gazebo>
  <gazebo reference="gripper_finger_3">
    <mu1>0.2</mu1>
    <mu2>0.2</mu2>
    <selfCollide>true</selfCollide>
  </gazebo>
  <gazebo reference="gripper_finger_4">
    <mu1>0.2</mu1>
    <mu2>0.2</mu2>
    <selfCollide>true</selfCollide>
  </gazebo>
  <gazebo reference="gripper_finger_5">
    <mu1>0.2</mu1>
    <mu2>0.2</mu2>
    <selfCollide>true</selfCollide>
  </gazebo>
  <gazebo reference="gripper_finger_6">
    <mu1>0.2</mu1>
    <mu2>0.2</mu2>
    <selfCollide>true</selfCollide>
  </gazebo>
  <!--ADDPOINT4END-->
  <link name="world"/>
  <joint name="world" type="fixed">
    <origin rpy="0 0 0" xyz="0 0 0.2"/>
    <parent link="world"/>
    <child link="base_link"/>
  </joint>
  <link name="eef_link"/>
  <joint name="tool0_ee_joint" type="fixed">
    <origin rpy="4.71238898038469 0 -1.5707963267948966" xyz="0.0 0 0"/>
    <!-- eef is at the center of gripper-->
    <parent link="tool0"/>
    <child link="eef_link"/>
  </joint>
  <link name="motoman_base">
    <visual>
      <geometry>
        <mesh filename="package://motoman_description/meshes/motoman_base/motoman_base.stl" scale="1 1 1"/>
      </geometry>
      <origin rpy="1.5707963267948966 0 1.5707963267948966" xyz="0 0 0"/>
      <material name="Green">
        <color rgba="0 1 0 0.5"/>
      </material>
    </visual>
    <collision>
      <geometry>
        <mesh filename="package://motoman_description/meshes/motoman_base/motoman_base.stl" scale="1 1 1"/>
      </geometry>
      <origin rpy="1.5707963267948966 0 1.5707963267948966" xyz="0 0 0"/>
    </collision>
  </link>
  <joint name="motoman_base_to_world" type="fixed">
    <parent link="world"/>
    <child link="motoman_base"/>
    <origin rpy="0 0 0" xyz="0.55 0.33 -0.5"/>
  </joint>

</robot>
